<?xml version='1.0' encoding='utf-8'?>
<robot name="OpenLoog">
  <mujoco>
    <compiler meshdir="meshes/" balanceinertia="true" discardvisual="false" />
  </mujoco>
  <link name="base_link">
    <inertial>
      <origin xyz="-0.0056641 -0.0013367 0.23829" rpy="0 0 0" />
      <mass value="22.447" />
      <inertia ixx="0.3742" ixy="0.0009471" ixz="0.004646" iyy="0.27691" iyz="0.0040142" izz="0.22104" />
    </inertial>
    <visual>
      <origin xyz="0 0 0" rpy="0 0 0" />
      <geometry>
        <mesh filename="package://AzureLoong/meshes/base_link.STL" />
      </geometry>
      <material name="">
        <color rgba="0.75294 0.75294 0.75294 1" />
      </material>
    </visual>
    <collision>
      <origin xyz="-0.002005314232257054 1.965569310469654e-17 0.20503974889837756" rpy="0.681516417863019 -9.510831300964214e-17 -1.5707963267948968" />
      <geometry>
        <box size="0.3273754417896271 0.36503949132581104 0.42854637797201894" /></geometry>
    </collision>
  </link>  
  <link name="Link_head_yaw">
    <inertial>
      <origin xyz="4.6974E-12 -0.0020814 0.044801" rpy="0 0 0" />
      <mass value="0.84249" />
      <inertia ixx="0.000629" ixy="1.2848E-14" ixz="-1.5461E-10" iyy="0.0007003" iyz="-6.5E-06" izz="0.0005541" />
    </inertial>
    <visual>
      <origin xyz="0 0 0" rpy="0 0 0" />
      <geometry>
        <mesh filename="package://AzureLoong/meshes/Link_head_yaw.STL" />
      </geometry>
      <material name="">
        <color rgba="0.89804 0.91765 0.92941 1" />
      </material>
    </visual>
    <collision>
      <origin xyz="-5.388446001104621e-18 -0.0023000007495284107 0.04285000031813979" rpy="-3.141592653589793 6.123233995736766e-17 -1.5707963267948968" />
      <geometry>
        <box size="0.06460000015795231 0.07999999821186066 0.09130000043660402" /></geometry>
    </collision>
  </link>
  <joint name="J_head_yaw" type="revolute">
    <origin xyz="0.009 0 0.4064" rpy="0 0 0" />
    <parent link="base_link" />
    <child link="Link_head_yaw" />
    <axis xyz="0 0 1" />
    <limit lower="-1.5708" upper="1.5708" effort="26" velocity="109.8" />
  </joint> 
  <link name="Link_head_pitch">
    <inertial>
      <origin xyz="0.020569 0.033004 0.125" rpy="0 0 0" />
      <mass value="1.3943" />
      <inertia ixx="0.0060059" ixy="9.4E-06" ixz="-0.0007564" iyy="0.00629" iyz="1.03E-05" izz="0.0048569" />
    </inertial>
    <visual>
      <origin xyz="0 0 0" rpy="0 0 0" />
      <geometry>
        <mesh filename="package://AzureLoong/meshes/Link_head_pitch.STL" />
      </geometry>
      <material name="">
        <color rgba="0.69804 0.69804 0.69804 1" />
      </material>
    </visual>
    <collision>
      <origin xyz="0.004569 0.033004 0.125" rpy="0.0 -0.0 0.0" />
      <geometry>
        <cylinder radius="0.09356938956827072" length="0.24085526634007692" /></geometry>
    </collision>
  </link>
  <joint name="J_head_pitch" type="revolute">
    <origin xyz="0 -0.0345999999999997 0.0484999999999999" rpy="0 0 0" />
    <parent link="Link_head_yaw" />
    <child link="Link_head_pitch" />
    <axis xyz="0 -1 0" />
    <limit lower="-0.7854" upper="0.7854" effort="26" velocity="109.8" />
  </joint>
  <link name="Link_arm_r_01">
    <inertial>
      <origin xyz="0.0044946 -0.038294 -1.8744E-06" rpy="0 0 0" />
      <mass value="0.75641" />
      <inertia ixx="0.00058712" ixy="-2.9803E-07" ixz="-5.8378E-09" iyy="0.00080305" iyz="3.6648E-08" izz="0.00084299" />
    </inertial>
    <visual>
      <origin xyz="0 0 0" rpy="0 0 0" />
      <geometry>
        <mesh filename="package://AzureLoong/meshes/Link_arm_r_01.STL" />
      </geometry>
      <material name="">
        <color rgba="0.69804 0.69804 0.69804 1" />
      </material>
    </visual>
    <collision>
      <origin xyz="-0.00019999966025352478 -0.0364999989978969 -2.46199309846825e-19" rpy="1.5707963267948966 1.5707963267948963 0.0" />
      <geometry>
        <box size="0.07599999755620956 0.0835999995470047 0.08499999437481165" /></geometry>
    </collision>
  </link>
  <joint name="J_arm_r_01" type="revolute">
    <origin xyz="0.004 -0.1616 0.3922" rpy="0 0 0" />
    <parent link="base_link" />
    <child link="Link_arm_r_01" />
    <axis xyz="0 -1 0" />
    <limit lower="-2.96706" upper="2.96706" effort="80" velocity="3.14" />
  </joint>
  <link name="Link_arm_r_02">
    <inertial>
      <origin xyz="0.042 -0.0674307499121858 -6.93889390390723E-18" rpy="0 0 0" />
      <mass value="0.984999996273518" />
      <inertia ixx="0.0017309882399251" ixy="9.79515256436727E-20" ixz="3.63988309726277E-19" iyy="0.00115401958000568" iyz="-4.42134220053852E-19" izz="0.00226269324370836" />
    </inertial>
    <visual>
      <origin xyz="0 0 0" rpy="0 0 0" />
      <geometry>
        <mesh filename="package://AzureLoong/meshes/Link_arm_r_02.STL" />
      </geometry>
      <material name="">
        <color rgba="0.698039215686274 0.698039215686274 0.698039215686274 1" />
      </material>
    </visual>
    <collision>
      <origin xyz="0.04199999989941716 -0.0464093703776598 -2.6999607212173396e-19" rpy="1.5707963267948968 1.5707963267948966 0.0" />
      <geometry>
        <box size="0.07599999755620956 0.10800000187009573 0.1523812673985958" /></geometry>
    </collision>
  </link>
  <joint name="J_arm_r_02" type="revolute">
    <origin xyz="-0.042 -0.041 0" rpy="0 0 0" />
    <parent link="Link_arm_r_01" />
    <child link="Link_arm_r_02" />
    <axis xyz="-1 0 0" />
    <limit lower="-1.83260" upper="1.83260" effort="80" velocity="3.14" />
  </joint>
  <link name="Link_arm_r_03">
    <inertial>
      <origin xyz="-0.00141357502419955 -0.164662742175383 0.0207578924800774" rpy="0 0 0" />
      <mass value="0.958999855228924" />
      <inertia ixx="0.00206438134078715" ixy="-1.82014067823509E-05" ixz="5.1283136963991E-06" iyy="0.00080535412926664" iyz="0.000255265992194607" izz="0.00205099914609259" />
    </inertial>
    <visual>
      <origin xyz="0 0 0" rpy="0 0 0" />
      <geometry>
        <mesh filename="package://AzureLoong/meshes/Link_arm_r_03.STL" />
      </geometry>
      <material name="">
        <color rgba="0.698039215686274 0.698039215686274 0.698039215686274 1" />
      </material>
    </visual>
    <collision>
      <origin xyz="-0.0035907567247734783 -0.10748496015079365 0.01636875606667013" rpy="1.4606519640175615 0.002005811287307379 -0.00024354989938328228" />
      <geometry>
        <box size="0.07793724111544645 0.08272916659551086 0.22364142748542531" /></geometry>
    </collision>
  </link>
  <joint name="J_arm_r_03" type="revolute">
    <origin xyz="0.042 -0.1226 0" rpy="0 0 0" />
    <parent link="Link_arm_r_02" />
    <child link="Link_arm_r_03" />
    <axis xyz="0 -1 0" />
    <limit lower="-2.96706" upper="2.96706" effort="48" velocity="3.14" />
  </joint>
  <link name="Link_arm_r_04">
    <inertial>
      <origin xyz="-0.038727 -0.060767 -0.021003" rpy="0 0 0" />
      <mass value="0.6" />
      <inertia ixx="0.00070398" ixy="2.023E-05" ixz="1.1263E-05" iyy="0.00068085" iyz="-0.00010585" izz="0.0010653" />
    </inertial>
    <visual>
      <origin xyz="0 0 0" rpy="0 0 0" />
      <geometry>
        <mesh filename="package://AzureLoong/meshes/Link_arm_r_04.STL" />
      </geometry>
      <material name="">
        <color rgba="0.69804 0.69804 0.69804 1" />
      </material>
    </visual>
    <collision>
      <origin xyz="-0.036699998658150434 -0.038699888411222426 -0.016136084116916347" rpy="3.141592653589793 1.2962792846817848 1.5707963267948963" />
      <geometry>
        <box size="0.0700463031850532 0.09969999734312296 0.14310730744646838" /></geometry>
    </collision>
  </link>
  <joint name="J_arm_r_04" type="revolute">
    <origin xyz="0.0353 -0.1774 0.024" rpy="0 0 0" />
    <parent link="Link_arm_r_03" />
    <child link="Link_arm_r_04" />
    <axis xyz="-1 0 0" />
    <limit lower="0" upper="2.96706" effort="48" velocity="3.14" />
  </joint>
  <link name="Link_arm_r_05">
    <inertial>
      <origin xyz="3.2712E-05 -0.068658 -0.00011178" rpy="0 0 0" />
      <mass value="0.68976" />
      <inertia ixx="0.0025225" ixy="-4E-07" ixz="8E-07" iyy="0.0004487" iyz="3.1E-06" izz="0.0024111" />
    </inertial>
    <visual>
      <origin xyz="0 0 0" rpy="0 0 0" />
      <geometry>
        <mesh filename="package://AzureLoong/meshes/Link_arm_r_05.STL" />
      </geometry>
      <material name="">
        <color rgba="0.69804 0.69804 0.69804 1" />
      </material>
    </visual>
    <collision>
      <origin xyz="-6.989149289607797e-18 -0.11250000445847402 -0.0" rpy="-1.5707963267948968 1.5707963267948966 0.0" />
      <geometry>
        <box size="0.060499999672174454 0.0949999988079071 0.22500000896444527" /></geometry>
    </collision>
  </link>
  <joint name="J_arm_r_05" type="revolute">
    <origin xyz="-0.0353 -0.1035 -0.024" rpy="0 0 0" />
    <parent link="Link_arm_r_04" />
    <child link="Link_arm_r_05" />
    <axis xyz="0 -1 0" />
    <limit lower="-2.96706" upper="2.96706" effort="12.4" velocity="6.28" />
  </joint>
  <link name="Link_arm_r_06">
    <inertial>
      <origin xyz="0.026078 -8.9588E-07 0.0016637" rpy="0 0 0" />
      <mass value="0.28" />
      <inertia ixx="0.0001456" ixy="-7.7026E-10" ixz="-2.1456E-07" iyy="0.00015693" iyz="-2.4102E-09" izz="0.00010498" />
    </inertial>
    <visual>
      <origin xyz="0 0 0" rpy="0 0 0" />
      <geometry>
        <mesh filename="package://AzureLoong/meshes/Link_arm_r_06.STL" />
      </geometry>
      <material name="">
        <color rgba="0.69804 0.69804 0.69804 1" />
      </material>
    </visual>
    <collision>
      <origin xyz="0.026500000618398186 -6.938893903907228e-18 0.0017610083875485572" rpy="0.0 -0.0 0.0" />
      <geometry>
        <sphere radius="0.035019154494572595" /></geometry>
    </collision>
  </link>
  <joint name="J_arm_r_06" type="revolute">
    <origin xyz="-0.0265 -0.1965 0" rpy="0 0 0" />
    <parent link="Link_arm_r_05" />
    <child link="Link_arm_r_06" />
    <axis xyz="1 0 0" />
    <limit lower="-1.8326" upper="1.8326" effort="12.4" velocity="6.28" />
  </joint>
  <link name="Link_arm_r_07">
    <inertial>
      <origin xyz="-0.007859 -0.15817 -0.027736" rpy="0 0 0" />
      <mass value="0.61354" />
      <inertia ixx="0.0025969" ixy="4.65E-05" ixz="-0.0001089" iyy="0.0007306" iyz="-1.47E-05" izz="0.0030104" />
    </inertial>
    <visual>
      <origin xyz="0 0 0" rpy="0 0 0" />
      <geometry>
        <mesh filename="package://AzureLoong/meshes/Link_arm_r_07.STL" />
      </geometry>
      <material name="">
        <color rgba="0.77647 0.75686 0.73725 1" />
      </material>
    </visual>
    <collision>
      <origin xyz="-0.023900139431431804 -0.13549153442793777 -0.020051703490835498" rpy="0.12369846308283265 1.4761600552272394 -1.487000383386563" />
      <geometry>
        <box size="0.07446015413122065 0.14150577388908692 0.3121386277707064" /></geometry>
    </collision>
  </link>
  <joint name="J_arm_r_07" type="revolute">
    <origin xyz="0.0265 0 0.0318" rpy="0 0 0" />
    <parent link="Link_arm_r_06" />
    <child link="Link_arm_r_07" />
    <axis xyz="0 0 1" />
    <limit lower="-1.04720" upper="1.04720" effort="12.4" velocity="6.28" />
  </joint>
  <link name="Link_arm_l_01">
    <inertial>
      <origin xyz="-0.00449464987882542 0.0382942125981936 -1.874402432607E-06" rpy="0 0 0" />
      <mass value="0.756406339732892" />
      <inertia ixx="0.000587115683146372" ixy="-2.98026052651538E-07" ixz="5.83781087215966E-09" iyy="0.000803052813361661" iyz="-3.66476835396106E-08" izz="0.000842985653484675" />
    </inertial>
    <visual>
      <origin xyz="0 0 0" rpy="0 0 0" />
      <geometry>
        <mesh filename="package://AzureLoong/meshes/Link_arm_l_01.STL" />
      </geometry>
      <material name="">
        <color rgba="0.698039215686274 0.698039215686274 0.698039215686274 1" />
      </material>
    </visual>
    <collision>
      <origin xyz="0.00019999966025352478 0.03649999899789691 2.4619930984682344e-19" rpy="1.5707963267948966 1.5707963267948963 0.0" />
      <geometry>
        <box size="0.07599999755620956 0.0835999995470047 0.08499999437481165" /></geometry>
    </collision>
  </link>
  <joint name="J_arm_l_01" type="revolute">
    <origin xyz="0.004 0.1616 0.3922" rpy="0 0 0" />
    <parent link="base_link" />
    <child link="Link_arm_l_01" />
    <axis xyz="0 1 0" />
    <limit lower="-2.96706" upper="2.96706" effort="80" velocity="3.14" />
  </joint>
  <link name="Link_arm_l_02">
    <inertial>
      <origin xyz="-0.042 0.0674307499121858 1.38777878078145E-17" rpy="0 0 0" />
      <mass value="0.984999996273518" />
      <inertia ixx="0.0017309882399251" ixy="1.48322871384691E-19" ixz="1.94588987195478E-19" iyy="0.00115401958000568" iyz="6.15989345249147E-19" izz="0.00226269324370836" />
    </inertial>
    <visual>
      <origin xyz="0 0 0" rpy="0 0 0" />
      <geometry>
        <mesh filename="package://AzureLoong/meshes/Link_arm_l_02.STL" />
      </geometry>
      <material name="">
        <color rgba="0.698039215686274 0.698039215686274 0.698039215686274 1" />
      </material>
    </visual>
    <collision>
      <origin xyz="-0.04199999989941716 0.0464093703776598 2.6999607212173396e-19" rpy="1.5707963267948966 1.5707963267948966 0.0" />
      <geometry>
        <box size="0.07599999755620956 0.10800000187009573 0.1523812673985958" /></geometry>
    </collision>
  </link>
  <joint name="J_arm_l_02" type="revolute">
    <origin xyz="0.042 0.041 0" rpy="0 0 0" />
    <parent link="Link_arm_l_01" />
    <child link="Link_arm_l_02" />
    <axis xyz="-1 0 0" />
    <limit lower="-1.83260" upper="1.83260" effort="80" velocity="3.14" />
  </joint>
  <link name="Link_arm_l_03">
    <inertial>
      <origin xyz="0.00141357502419956 0.164662742175383 0.0207578924800774" rpy="0 0 0" />
      <mass value="0.958999855228925" />
      <inertia ixx="0.00206438134078715" ixy="-1.82014067823508E-05" ixz="-5.12831369639908E-06" iyy="0.000805354129266641" iyz="-0.000255265992194607" izz="0.00205099914609259" />
    </inertial>
    <visual>
      <origin xyz="0 0 0" rpy="0 0 0" />
      <geometry>
        <mesh filename="package://AzureLoong/meshes/Link_arm_l_03.STL" />
      </geometry>
      <material name="">
        <color rgba="0.698039215686274 0.698039215686274 0.698039215686274 1" />
      </material>
    </visual>
    <collision>
      <origin xyz="0.0035907567247734683 0.10748496015079359 0.016368756066670122" rpy="1.4606519640175615 0.0020058112873073785 3.14134910369041" />
      <geometry>
        <box size="0.07793724111544645 0.08272916659551086 0.22364142748542543" /></geometry>
    </collision>
  </link>
  <joint name="J_arm_l_03" type="revolute">
    <origin xyz="-0.042 0.1226 0" rpy="0 0 0" />
    <parent link="Link_arm_l_02" />
    <child link="Link_arm_l_03" />
    <axis xyz="0 1 0" />
    <limit lower="-2.96706" upper="2.96706" effort="48" velocity="3.14" />
  </joint>
  <link name="Link_arm_l_04">
    <inertial>
      <origin xyz="0.038726985904266 0.0607672244593032 -0.0210032450980798" rpy="0 0 0" />
      <mass value="0.60000012303258" />
      <inertia ixx="0.000703976141425558" ixy="2.02301178076816E-05" ixz="-1.12633779930363E-05" iyy="0.000680850033983237" iyz="0.000105852227353173" izz="0.00106526266740194" />
    </inertial>
    <visual>
      <origin xyz="0 0 0" rpy="0 0 0" />
      <geometry>
        <mesh filename="package://AzureLoong/meshes/Link_arm_l_04.STL" />
      </geometry>
      <material name="">
        <color rgba="0.698039215686274 0.698039215686274 0.698039215686274 1" />
      </material>
    </visual>
    <collision>
      <origin xyz="0.036699998658150434 0.038699888411222426 -0.01613608411691635" rpy="3.141592653589793 -1.2962792846817848 1.5707963267948968" />
      <geometry>
        <box size="0.0700463031850532 0.09969999734312296 0.14310730744646838" /></geometry>
    </collision>
  </link>
  <joint name="J_arm_l_04" type="revolute">
    <origin xyz="-0.0353 0.1774 0.024" rpy="0 0 0" />
    <parent link="Link_arm_l_03" />
    <child link="Link_arm_l_04" />
    <axis xyz="1 0 0" />
    <limit lower="0" upper="2.96706" effort="48" velocity="3.14" />
  </joint>
  <link name="Link_arm_l_05">
    <inertial>
      <origin xyz="-3.2712E-05 0.068658 -0.00011178" rpy="0 0 0" />
      <mass value="0.68976" />
      <inertia ixx="0.0025225" ixy="-4E-07" ixz="-8E-07" iyy="0.0004487" iyz="-3.1E-06" izz="0.0024111" />
    </inertial>
    <visual>
      <origin xyz="0 0 0" rpy="0 0 0" />
      <geometry>
        <mesh filename="package://AzureLoong/meshes/Link_arm_l_05.STL" />
      </geometry>
      <material name="">
        <color rgba="0.69804 0.69804 0.69804 1" />
      </material>
    </visual>
    <collision>
      <origin xyz="-5.025538570057275e-20 0.11250000445847397 -0.0" rpy="1.5707963267948968 1.5707963267948966 0.0" />
      <geometry>
        <box size="0.060499999672174454 0.0949999988079071 0.2250000089644455" /></geometry>
    </collision>
  </link>
  <joint name="J_arm_l_05" type="revolute">
    <origin xyz="0.0353 0.1035 -0.024" rpy="0 0 0" />
    <parent link="Link_arm_l_04" />
    <child link="Link_arm_l_05" />
    <axis xyz="0 1 0" />
    <limit lower="-2.96706" upper="2.96706" effort="12.4" velocity="6.28" />
  </joint>
  <link name="Link_arm_l_06">
    <inertial>
      <origin xyz="-0.0260776548825596 8.95877202866657E-07 0.00166373234012217" rpy="0 0 0" />
      <mass value="0.280000012776158" />
      <inertia ixx="0.000145596926990102" ixy="-7.70263046256849E-10" ixz="2.14557176368931E-07" iyy="0.000156926535065694" iyz="2.41022657678511E-09" izz="0.000104981940665913" />
    </inertial>
    <visual>
      <origin xyz="0 0 0" rpy="0 0 0" />
      <geometry>
        <mesh filename="package://AzureLoong/meshes/Link_arm_l_06.STL" />
      </geometry>
      <material name="">
        <color rgba="0.698039215686274 0.698039215686274 0.698039215686274 1" />
      </material>
    </visual>
    <collision>
      <origin xyz="-0.026500000618398196 0.0 0.0017610083875485572" rpy="0.0 -0.0 0.0" />
      <geometry>
        <sphere radius="0.03501915449457261" /></geometry>
    </collision>
  </link>
  <joint name="J_arm_l_06" type="revolute">
    <origin xyz="0.0265 0.1965 0" rpy="0 0 0" />
    <parent link="Link_arm_l_05" />
    <child link="Link_arm_l_06" />
    <axis xyz="-1 0 0" />
    <limit lower="-1.8326" upper="1.8326" effort="12.4" velocity="6.28" />
  </joint>
  <link name="Link_arm_l_07">
    <inertial>
      <origin xyz="-0.0077872 0.15705 -0.027733" rpy="0 0 0" />
      <mass value="0.61354" />
      <inertia ixx="0.0025964" ixy="-4.66E-05" ixz="-0.0001089" iyy="0.0007306" iyz="1.47E-05" izz="0.00301" />
    </inertial>
    <visual>
      <origin xyz="0 0 0" rpy="0 0 0" />
      <geometry>
        <mesh filename="package://AzureLoong/meshes/Link_arm_l_07.STL" />
      </geometry>
      <material name="">
        <color rgba="0.77647 0.75686 0.73725 1" />
      </material>
    </visual>
    <collision>
      <origin xyz="-0.02392460755447107 0.13548432560846652 -0.020236280738095466" rpy="-0.040255684516358296 1.479617258229825 1.5707963267948968" />
      <geometry>
        <box size="0.07420478960456942 0.14182928051113333 0.3122642579482233" /></geometry>
    </collision>
  </link>
  <joint name="J_arm_l_07" type="revolute">
    <origin xyz="-0.0265 0 0.0318" rpy="0 0 0" />
    <parent link="Link_arm_l_06" />
    <child link="Link_arm_l_07" />
    <axis xyz="0 0 1" />
    <limit lower="-1.04720" upper="1.04720" effort="12.4" velocity="6.28" />
  </joint>
  <link name="Link_waist_pitch">
    <inertial>
      <origin xyz="-0.00073496 0.049925 -2.9695E-05" rpy="0 0 0" />
      <mass value="2.6964" />
      <inertia ixx="0.0051971" ixy="-4.37E-05" ixz="3E-07" iyy="0.0047413" iyz="6E-06" izz="0.0061906" />
    </inertial>
    <visual>
      <origin xyz="0 0 0" rpy="0 0 0" />
      <geometry>
        <mesh filename="package://AzureLoong/meshes/Link_waist_pitch.STL" />
      </geometry>
      <material name="">
        <color rgba="0.69804 0.69804 0.69804 1" />
      </material>
    </visual>
    <collision>
      <origin xyz="0.0020000003278255506 0.07050000154413283 -0.0" rpy="1.5707963267948968 1.5707963267948966 0.0" />
      <geometry>
        <box size="0.11948809772729874 0.14000000804662704 0.14300000621005893" /></geometry>
    </collision>
  </link>
  <joint name="J_waist_pitch" type="revolute">
    <origin xyz="0 -0.06525 0" rpy="0 0 0" />
    <parent link="base_link" />
    <child link="Link_waist_pitch" />
    <axis xyz="0 -1 0" />
    <limit lower="-0.29671" upper="0.78540" effort="315" velocity="3.72" />
  </joint>
  <link name="Link_waist_roll">
    <inertial>
      <origin xyz="-0.0037424 -0.001 -0.016856" rpy="0 0 0" />
      <mass value="2.9806" />
      <inertia ixx="0.0071327" ixy="0" ixz="-0.00358" iyy="0.018825" iyz="0" izz="0.016056" />
    </inertial>
    <visual>
      <origin xyz="0 0 0" rpy="0 0 0" />
      <geometry>
        <mesh filename="package://AzureLoong/meshes/Link_waist_roll.STL" />
      </geometry>
      <material name="">
        <color rgba="0.8902 0.8902 0.91373 1" />
      </material>
    </visual>
    <collision>
      <origin xyz="0.03749999776482582 -0.000999998301267624 -0.019750000908970833" rpy="1.5707963267948966 -0.0 1.5707963267948966" />
      <geometry>
        <box size="0.11984597891569138 0.15949999913573265 0.23099999874830246" /></geometry>
    </collision>
  </link>
  <joint name="J_waist_roll" type="revolute">
    <origin xyz="-0.064 0.0655 0" rpy="0 0 0" />
    <parent link="Link_waist_pitch" />
    <child link="Link_waist_roll" />
    <axis xyz="1 0 0" />
    <limit lower="-0.69813" upper="0.69813" effort="315" velocity="3.72" />
  </joint>
  <link name="Link_waist_yaw">
    <inertial>
      <origin xyz="-0.096172 -0.001 -0.057836" rpy="0 0 0" />
      <mass value="7.3588" />
      <inertia ixx="0.091635" ixy="0" ixz="0.0058036" iyy="0.032766" iyz="0" izz="0.10764" />
    </inertial>
    <visual>
      <origin xyz="0 0 0" rpy="0 0 0" />
      <geometry>
        <mesh filename="package://AzureLoong/meshes/Link_waist_yaw.STL" />
      </geometry>
      <material name="">
        <color rgba="0.8902 0.8902 0.91373 1" />
      </material>
    </visual>
    <collision>
      <origin xyz="-0.04885000362992286 -0.0010000020265579265 -0.06647792912553996" rpy="-1.5707963267948966 -1.5707963267948966 0.0" />
      <geometry>
        <box size="0.13895585224963725 0.24769999831914902 0.37378689646720886" /></geometry>
    </collision>
  </link>
  <joint name="J_waist_yaw" type="revolute">
    <origin xyz="0.0675 0 -0.098" rpy="0 0 0" />
    <parent link="Link_waist_roll" />
    <child link="Link_waist_yaw" />
    <axis xyz="0 0 1" />
    <limit lower="-0.78540" upper="0.78540" effort="121" velocity="5.92" />
  </joint>
  <link name="Link_hip_r_roll">
    <inertial>
      <origin xyz="0.075725 -0.0010616 0.016591" rpy="0 0 0" />
      <mass value="2.4334" />
      <inertia ixx="0.0036961" ixy="-9E-07" ixz="0.0001644" iyy="0.0045067" iyz="6.3E-06" izz="0.0039063" />
    </inertial>
    <visual>
      <origin xyz="0 0 0" rpy="0 0 0" />
      <geometry>
        <mesh filename="package://AzureLoong/meshes/Link_hip_r_roll.STL" />
      </geometry>
      <material name="">
        <color rgba="0.89804 0.91765 0.92941 1" />
      </material>
    </visual>
    <collision>
      <origin xyz="0.06664533359700563 0.002838913719310106 0.01887310041090572" rpy="1.9194156048821496 1.5337999101432476 1.5707963267948966" />
      <geometry>
        <box size="0.10938711969958106 0.11348148586759206 0.1466289123198961" /></geometry>
    </collision>
  </link>
  <joint name="J_hip_r_roll" type="revolute">
    <origin xyz="-0.0875 -0.12 -0.069" rpy="0 0 0" />
    <parent link="Link_waist_yaw" />
    <child link="Link_hip_r_roll" />
    <axis xyz="1 0 0" />
    <limit lower="-0.17453" upper="0.43633" effort="320" velocity="20.94" />
  </joint>
  <link name="Link_hip_r_yaw">
    <inertial>
      <origin xyz="-3.0911E-08 -0.0071356 -0.10063" rpy="0 0 0" />
      <mass value="3.4303" />
      <inertia ixx="0.0077365" ixy="0" ixz="0" iyy="0.0080807" iyz="0.0001167" izz="0.006641" />
    </inertial>
    <visual>
      <origin xyz="0 0 0" rpy="0 0 0" />
      <geometry>
        <mesh filename="package://AzureLoong/meshes/Link_hip_r_yaw.STL" />
      </geometry>
      <material name="">
        <color rgba="0.89804 0.91765 0.92941 1" />
      </material>
    </visual>
    <collision>
      <origin xyz="-6.146728992498745e-07 -0.02987500093877315 -0.09949999395757914" rpy="-3.141592653589793 0.0 1.5707963267948966" />
      <geometry>
        <box size="0.13824999704957008 0.15199876576662064 0.16399998776614666" /></geometry>
    </collision>
  </link>
  <joint name="J_hip_r_yaw" type="revolute">
    <origin xyz="0.08225 -0.001 -0.01" rpy="0 0 0" />
    <parent link="Link_hip_r_roll" />
    <child link="Link_hip_r_yaw" />
    <axis xyz="0 0 1" />
    <limit lower="-0.69813" upper="0.69813" effort="160" velocity="19.63" />
  </joint>
  <link name="Link_hip_r_pitch">
    <inertial>
      <origin xyz="0.0010856 -0.05497 -0.14535" rpy="0 0 0" />
      <mass value="5.2378" />
      <inertia ixx="0.043457" ixy="0.0002478" ixz="-0.0007626" iyy="0.037801" iyz="-0.0007431" izz="0.015183" />
    </inertial>
    <visual>
      <origin xyz="0 0 0" rpy="0 0 0" />
      <geometry>
        <mesh filename="package://AzureLoong/meshes/Link_hip_r_pitch.STL" />
      </geometry>
      <material name="">
        <color rgba="0.69804 0.69804 0.69804 1" />
      </material>
    </visual>
    <collision>
      <origin xyz="0.003690143681798986 -0.058575004339450266 -0.18734361991381673" rpy="0.005925451270874616 0.09424358761539621 -3.1349431531897416" />
      <geometry>
        <box size="0.12843006439604737 0.15761262328366868 0.47204802623524966" /></geometry>
    </collision>
  </link>
  <joint name="J_hip_r_pitch" type="revolute">
    <origin xyz="0 0.03675 -0.1055" rpy="0 0 0" />
    <parent link="Link_hip_r_yaw" />
    <child link="Link_hip_r_pitch" />
    <axis xyz="0 -1 0" />
    <limit lower="-0.78540" upper="1.83260" effort="396" velocity="19.16" />
  </joint>
  <link name="Link_knee_r_pitch">
    <inertial>
      <origin xyz="-0.0096425 2.9338E-06 -0.13601" rpy="0 0 0" />
      <mass value="2.9775" />
      <inertia ixx="0.02386" ixy="6.76E-05" ixz="-0.0004656" iyy="0.024184" iyz="-0.0005481" izz="0.0023083" />
    </inertial>
    <visual>
      <origin xyz="0 0 0" rpy="0 0 0" />
      <geometry>
        <mesh filename="package://AzureLoong/meshes/Link_knee_r_pitch.STL" />
      </geometry>
      <material name="">
        <color rgba="0.66667 0.69804 0.76863 1" />
      </material>
    </visual>
    <collision>
      <origin xyz="-0.016366676075426235 0.0018393083305750849 -0.17232882217954293" rpy="3.105094431773144 0.04012570478521281 -1.568867414157791" />
      <geometry>
        <box size="0.08305011195946374 0.10171538619274088 0.4700031674581286" /></geometry>
    </collision>
  </link>
  <joint name="J_knee_r_pitch" type="revolute">
    <origin xyz="0 -0.01125 -0.4" rpy="0 0 0" />
    <parent link="Link_hip_r_pitch" />
    <child link="Link_knee_r_pitch" />
    <axis xyz="0 -1 0" />
    <limit lower="-2.35619" upper="0.08727" effort="396" velocity="19.16" />
  </joint>
  <link name="Link_ankle_r_pitch">
    <inertial>
      <origin xyz="-6.1835E-12 -1.2655E-07 -2.4682E-08" rpy="0 0 0" />
      <mass value="0.10145" />
      <inertia ixx="2.7175E-05" ixy="1.0023E-14" ixz="-8.1752E-13" iyy="6.1118E-06" iyz="2.6285E-11" izz="2.6565E-05" />
    </inertial>
    <visual>
      <origin xyz="0 0 0" rpy="0 0 0" />
      <geometry>
        <mesh filename="package://AzureLoong/meshes/Link_ankle_r_pitch.STL" />
      </geometry>
      <material name="">
        <color rgba="0.52941 0.54902 0.54902 1" />
      </material>
    </visual>
    <collision>
      <origin xyz="3.421623629929553e-25 1.862645149230957e-09 -4.563480615615845e-08" rpy="1.5707963267948966 -0.0 -1.8369701987210297e-16" />
      <geometry>
        <box size="0.02199999988079071 0.02199999988079071 0.0608999989926815" /></geometry>
    </collision>
  </link>
  <joint name="J_ankle_r_pitch" type="revolute">
    <origin xyz="0 0 -0.387" rpy="0 0 0" />
    <parent link="Link_knee_r_pitch" />
    <child link="Link_ankle_r_pitch" />
    <axis xyz="0 -1 0" />
    <limit lower="-0.43633" upper="0.61087" effort="58.5" velocity="48.8" />
  </joint>
  <link name="Link_ankle_r_roll">
    <inertial>
      <origin xyz="0.041078 -8.9152E-08 -0.043909" rpy="0 0 0" />
      <mass value="0.75229" />
      <inertia ixx="0.0004393" ixy="0" ixz="-0.000269" iyy="0.0036465" iyz="0" izz="0.0036369" />
    </inertial>
    <visual>
      <origin xyz="0 0 0" rpy="0 0 0" />
      <geometry>
        <mesh filename="package://AzureLoong/meshes/Link_ankle_r_roll.STL" />
      </geometry>
      <material name="">
        <color rgba="0.89804 0.91765 0.92941 1" />
      </material>
    </visual>
    <collision>
      <origin xyz="0.04750461363863139 8.266688098764184e-05 -0.02654531035541249" rpy="-1.570601476610124 0.0023771746030417148 1.5707963267948968" />
      <geometry>
        <box size="0.08003152899406105 0.08708268283896033 0.2450051728352756" /></geometry>
    </collision>
  </link>
  <joint name="J_ankle_r_roll" type="revolute">
    <origin xyz="0 0 0" rpy="0 0 0" /> 
    <parent link="Link_ankle_r_pitch" />
    <child link="Link_ankle_r_roll" />
    <axis xyz="1 0 0" />
    <limit lower="-0.43633" upper="0.43633" effort="58.5" velocity="48.8" />
  </joint>
  
  
  <link name="Link_hip_l_roll">
    <inertial>
      <origin xyz="0.075725 -0.00093843 0.016591" rpy="0 0 0" />
      <mass value="2.4334" />
      <inertia ixx="0.0034464" ixy="9E-07" ixz="0.0001904" iyy="0.0042569" iyz="-6.6E-06" izz="0.0039063" />
    </inertial>
    <visual>
      <origin xyz="0 0 0" rpy="0 0 0" />
      <geometry>
        <mesh filename="package://AzureLoong/meshes/Link_hip_l_roll.STL" />
      </geometry>
      <material name="">
        <color rgba="0.89804 0.91765 0.92941 1" />
      </material>
    </visual>
    <collision>
      <origin xyz="0.0663826449459969 -0.0047114262679623 0.018888862674006055" rpy="-1.7552637441547307 1.528726961248851 -1.40401235857474" />
      <geometry>
        <box size="0.10953407117352178 0.11355194626876655 0.14642735745762184" /></geometry>
    </collision>

  </link>
  <joint name="J_hip_l_roll" type="revolute">
    <origin xyz="-0.0875 0.12 -0.069" rpy="0 0 0" />
    <parent link="Link_waist_yaw" />
    <child link="Link_hip_l_roll" />
    <axis xyz="1 0 0" />
    <limit lower="-0.17453" upper="0.43633" effort="320" velocity="20.94" />
  </joint>
  <link name="Link_hip_l_yaw">
    <inertial>
      <origin xyz="-3.1716E-08 0.0071358 -0.10063" rpy="0 0 0" />
      <mass value="3.4304" />
      <inertia ixx="0.0077365" ixy="0" ixz="0" iyy="0.0080807" iyz="-0.0001167" izz="0.0066409" />
    </inertial>
    <visual>
      <origin xyz="0 0 0" rpy="0 0 0" />
      <geometry>
        <mesh filename="package://AzureLoong/meshes/Link_hip_l_yaw.STL" />
      </geometry>
      <material name="">
        <color rgba="0.89804 0.91765 0.92941 1" />
      </material>
    </visual>
    <collision>
      <origin xyz="6.146728992462158e-07 0.029875000938773155 -0.09949999395757914" rpy="-3.141592653589793 0.0 -1.5707963267948966" />
      <geometry>
        <box size="0.13824999704957008 0.15199876576662064 0.16399998776614666" /></geometry>
    </collision>
  </link>
  <joint name="J_hip_l_yaw" type="revolute">
    <origin xyz="0.08225 -0.001 -0.01" rpy="0 0 0" />
    <parent link="Link_hip_l_roll" />
    <child link="Link_hip_l_yaw" />
    <axis xyz="0 0 1" />
    <limit lower="-0.69813" upper="0.69813" effort="160" velocity="19.63" />
  </joint>
  <link name="Link_hip_l_pitch">
    <inertial>
      <origin xyz="0.0010856 0.05497 -0.14535" rpy="0 0 0" />
      <mass value="5.2378" />
      <inertia ixx="0.043457" ixy="-0.0002479" ixz="-0.0007626" iyy="0.037801" iyz="0.0007431" izz="0.015183" />
    </inertial>
    <visual>
      <origin xyz="0 0 0" rpy="0 0 0" />
      <geometry>
        <mesh filename="package://AzureLoong/meshes/Link_hip_l_pitch.STL" />
      </geometry>
      <material name="">
        <color rgba="0.69804 0.69804 0.69804 1" />
      </material>
    </visual>
    <collision>
      <origin xyz="0.0014642016092440264 0.058249998837709434 -0.18771507537857599" rpy="-3.141592653589793 -0.03842855541594409 -3.062974209393719e-16" />
      <geometry>
        <box size="0.1286939637515551 0.15699999779462814 0.47319313536392066" /></geometry>
    </collision>
  </link>
  <joint name="J_hip_l_pitch" type="revolute">
    <origin xyz="0 -0.03675 -0.1055" rpy="0 0 0" />
    <parent link="Link_hip_l_yaw" />
    <child link="Link_hip_l_pitch" />
    <axis xyz="0 -1 0" />
    <limit lower="-0.78540" upper="1.83260" effort="396" velocity="19.16" />
  </joint>
  <link name="Link_knee_l_pitch">
    <inertial>
      <origin xyz="-0.0096425 -2.8684E-06 -0.13601" rpy="0 0 0" />
      <mass value="2.9775" />
      <inertia ixx="0.023859" ixy="-6.76E-05" ixz="-0.0004656" iyy="0.024183" iyz="0.000548" izz="0.0023083" />
    </inertial>
    <visual>
      <origin xyz="0 0 0" rpy="0 0 0" />
      <geometry>
        <mesh filename="package://AzureLoong/meshes/Link_knee_l_pitch.STL" />
      </geometry>
      <material name="">
        <color rgba="0.66667 0.69804 0.76863 1" />
      </material>
    </visual>
    <collision>
      <origin xyz="-0.016274758282985937 -0.001856433296903476 -0.17235459103943276" rpy="3.1056360985523974 -0.04039104665859481 -1.569343773743853" />
      <geometry>
        <box size="0.0830744339109904 0.10167547683539807 0.470009645389421" /></geometry>
    </collision>
  </link>
  <joint name="J_knee_l_pitch" type="revolute">
    <origin xyz="0 0.01125 -0.4" rpy="0 0 0" />
    <parent link="Link_hip_l_pitch" />
    <child link="Link_knee_l_pitch" />
    <axis xyz="0 -1 0" />
    <limit lower="-2.35619" upper="0.08727" effort="396" velocity="19.16" />
  </joint>
  <link name="Link_ankle_l_pitch">
    <inertial>
      <origin xyz="-6.1835E-12 1.2655E-07 6.7022E-08" rpy="0 0 0" />
      <mass value="0.10145" />
      <inertia ixx="2.7175E-05" ixy="-1.0023E-14" ixz="-8.1752E-13" iyy="6.1118E-06" iyz="-2.6285E-11" izz="2.6565E-05" />
    </inertial>
    <visual>
      <origin xyz="0 0 0" rpy="0 0 0" />
      <geometry>
        <mesh filename="package://AzureLoong/meshes/Link_ankle_l_pitch.STL" />
      </geometry>
      <material name="">
        <color rgba="0.52941 0.54902 0.54902 1" />
      </material>
    </visual>
    <collision>
      <origin xyz="-1.1405412099765178e-25 -1.862645149230957e-09 4.563480615615845e-08" rpy="1.5707963267948966 -0.0 3.141592653589793" />
      <geometry>
        <box size="0.02199999988079071 0.02199999988079071 0.0608999989926815" /></geometry>
    </collision>
  </link>
  <joint name="J_ankle_l_pitch" type="revolute">
    <origin xyz="0 0 -0.387" rpy="0 0 0" />
    <parent link="Link_knee_l_pitch" />
    <child link="Link_ankle_l_pitch" />
    <axis xyz="0 -1 0" />
    <limit lower="-0.43644" upper="0.61087" effort="58.5" velocity="48.8" />
  </joint>
  <link name="Link_ankle_l_roll">
    <inertial>
      <origin xyz="0.041077 -2.9318E-08 -0.043909" rpy="0 0 0" />
      <mass value="0.7522882" />
      <inertia ixx="0.0004393" ixy="0" ixz="-0.000269" iyy="0.0036465" iyz="0" izz="0.0036369" />
    </inertial>
    <visual>
      <origin xyz="0 0 0" rpy="0 0 0" />
      <geometry>
        <mesh filename="package://AzureLoong/meshes/Link_ankle_l_roll.STL" />
      </geometry>
      <material name="">
        <color rgba="0.89804 0.91765 0.92941 1" />
      </material>
    </visual>
    <collision>
      <origin xyz="0.04749999940395355 0.0012208642475975968 -0.02722398766749333" rpy="1.5707963267948966 0.03579092791791763 1.5707963267948966" />
      <geometry>
        <box size="0.08042679535932826 0.08830404889775641 0.24500000476837158" /></geometry>
    </collision>
  </link>
  <joint name="J_ankle_l_roll" type="revolute">
    <origin xyz="0 0 0" rpy="0 0 0" />
    <parent link="Link_ankle_l_pitch" />
    <child link="Link_ankle_l_roll" />
    <axis xyz="1 0 0" />
    <limit lower="-0.43633" upper="0.43633" effort="58.5" velocity="48.8" />
  </joint>
</robot>
